<?xml version="1.0" ?>
<!-- =================================================================================== -->
<!-- |    This document was autogenerated by xacro from amr_ust.xacro                  | -->
<!-- |    EDITING THIS FILE BY HAND IS NOT RECOMMENDED                                 | -->
<!-- =================================================================================== -->
<robot name="amr_ust">
  <material name="silver">
    <color rgba="0.700 0.700 0.700 1.000"/>
  </material>
  <material name="black">
    <color rgba="0.0 0.0 0.0 1.000"/>
  </material>
  <material name="yellow">
    <color rgba="0.255 0.180 0.020 1.000"/>
  </material>
  <transmission name="Revolute 1_tran">
    <type>transmission_interface/SimpleTransmission</type>
    <joint name="Revolute 1">
      <hardwareInterface>hardware_interface/EffortJointInterface</hardwareInterface>
    </joint>
    <actuator name="Revolute 1_actr">
      <hardwareInterface>hardware_interface/EffortJointInterface</hardwareInterface>
      <mechanicalReduction>1</mechanicalReduction>
    </actuator>
  </transmission>
  <transmission name="Revolute 2_tran">
    <type>transmission_interface/SimpleTransmission</type>
    <joint name="Revolute 2">
      <hardwareInterface>hardware_interface/EffortJointInterface</hardwareInterface>
    </joint>
    <actuator name="Revolute 2_actr">
      <hardwareInterface>hardware_interface/EffortJointInterface</hardwareInterface>
      <mechanicalReduction>1</mechanicalReduction>
    </actuator>
  </transmission>
  <transmission name="Revolute 3_tran">
    <type>transmission_interface/SimpleTransmission</type>
    <joint name="Revolute 3">
      <hardwareInterface>hardware_interface/EffortJointInterface</hardwareInterface>
    </joint>
    <actuator name="Revolute 3_actr">
      <hardwareInterface>hardware_interface/EffortJointInterface</hardwareInterface>
      <mechanicalReduction>1</mechanicalReduction>
    </actuator>
  </transmission>
  <transmission name="Revolute 4_tran">
    <type>transmission_interface/SimpleTransmission</type>
    <joint name="Revolute 4">
      <hardwareInterface>hardware_interface/EffortJointInterface</hardwareInterface>
    </joint>
    <actuator name="Revolute 4_actr">
      <hardwareInterface>hardware_interface/EffortJointInterface</hardwareInterface>
      <mechanicalReduction>1</mechanicalReduction>
    </actuator>
  </transmission>
  <transmission name="Revolute 5_tran">
    <type>transmission_interface/SimpleTransmission</type>
    <joint name="Revolute 5">
      <hardwareInterface>hardware_interface/EffortJointInterface</hardwareInterface>
    </joint>
    <actuator name="Revolute 5_actr">
      <hardwareInterface>hardware_interface/EffortJointInterface</hardwareInterface>
      <mechanicalReduction>1</mechanicalReduction>
    </actuator>
  </transmission>
  <transmission name="Revolute 6_tran">
    <type>transmission_interface/SimpleTransmission</type>
    <joint name="Revolute 6">
      <hardwareInterface>hardware_interface/EffortJointInterface</hardwareInterface>
    </joint>
    <actuator name="Revolute 6_actr">
      <hardwareInterface>hardware_interface/EffortJointInterface</hardwareInterface>
      <mechanicalReduction>1</mechanicalReduction>
    </actuator>
  </transmission>
  <transmission name="Revolute 7_tran">
    <type>transmission_interface/SimpleTransmission</type>
    <joint name="Revolute 7">
      <hardwareInterface>hardware_interface/EffortJointInterface</hardwareInterface>
    </joint>
    <actuator name="Revolute 7_actr">
      <hardwareInterface>hardware_interface/EffortJointInterface</hardwareInterface>
      <mechanicalReduction>1</mechanicalReduction>
    </actuator>
  </transmission>
  <transmission name="Revolute 8_tran">
    <type>transmission_interface/SimpleTransmission</type>
    <joint name="Revolute 8">
      <hardwareInterface>hardware_interface/EffortJointInterface</hardwareInterface>
    </joint>
    <actuator name="Revolute 8_actr">
      <hardwareInterface>hardware_interface/EffortJointInterface</hardwareInterface>
      <mechanicalReduction>1</mechanicalReduction>
    </actuator>
  </transmission>
  <transmission name="Revolute 9_tran">
    <type>transmission_interface/SimpleTransmission</type>
    <joint name="Revolute 9">
      <hardwareInterface>hardware_interface/EffortJointInterface</hardwareInterface>
    </joint>
    <actuator name="Revolute 9_actr">
      <hardwareInterface>hardware_interface/EffortJointInterface</hardwareInterface>
      <mechanicalReduction>1</mechanicalReduction>
    </actuator>
  </transmission>
  <transmission name="Revolute 10_tran">
    <type>transmission_interface/SimpleTransmission</type>
    <joint name="Revolute 10">
      <hardwareInterface>hardware_interface/EffortJointInterface</hardwareInterface>
    </joint>
    <actuator name="Revolute 10_actr">
      <hardwareInterface>hardware_interface/EffortJointInterface</hardwareInterface>
      <mechanicalReduction>1</mechanicalReduction>
    </actuator>
  </transmission>
  <transmission name="Revolute 11_tran">
    <type>transmission_interface/SimpleTransmission</type>
    <joint name="Revolute 11">
      <hardwareInterface>hardware_interface/EffortJointInterface</hardwareInterface>
    </joint>
    <actuator name="Revolute 11_actr">
      <hardwareInterface>hardware_interface/EffortJointInterface</hardwareInterface>
      <mechanicalReduction>1</mechanicalReduction>
    </actuator>
  </transmission>
  <transmission name="Revolute 12_tran">
    <type>transmission_interface/SimpleTransmission</type>
    <joint name="Revolute 12">
      <hardwareInterface>hardware_interface/EffortJointInterface</hardwareInterface>
    </joint>
    <actuator name="Revolute 12_actr">
      <hardwareInterface>hardware_interface/EffortJointInterface</hardwareInterface>
      <mechanicalReduction>1</mechanicalReduction>
    </actuator>
  </transmission>
  <transmission name="Revolute 13_tran">
    <type>transmission_interface/SimpleTransmission</type>
    <joint name="Revolute 13">
      <hardwareInterface>hardware_interface/EffortJointInterface</hardwareInterface>
    </joint>
    <actuator name="Revolute 13_actr">
      <hardwareInterface>hardware_interface/EffortJointInterface</hardwareInterface>
      <mechanicalReduction>1</mechanicalReduction>
    </actuator>
  </transmission>
  <transmission name="Revolute 14_tran">
    <type>transmission_interface/SimpleTransmission</type>
    <joint name="Revolute 14">
      <hardwareInterface>hardware_interface/EffortJointInterface</hardwareInterface>
    </joint>
    <actuator name="Revolute 14_actr">
      <hardwareInterface>hardware_interface/EffortJointInterface</hardwareInterface>
      <mechanicalReduction>1</mechanicalReduction>
    </actuator>
  </transmission>
  <transmission name="Revolute 15_tran">
    <type>transmission_interface/SimpleTransmission</type>
    <joint name="Revolute 15">
      <hardwareInterface>hardware_interface/EffortJointInterface</hardwareInterface>
    </joint>
    <actuator name="Revolute 15_actr">
      <hardwareInterface>hardware_interface/EffortJointInterface</hardwareInterface>
      <mechanicalReduction>1</mechanicalReduction>
    </actuator>
  </transmission>
  <transmission name="Revolute 16_tran">
    <type>transmission_interface/SimpleTransmission</type>
    <joint name="Revolute 16">
      <hardwareInterface>hardware_interface/EffortJointInterface</hardwareInterface>
    </joint>
    <actuator name="Revolute 16_actr">
      <hardwareInterface>hardware_interface/EffortJointInterface</hardwareInterface>
      <mechanicalReduction>1</mechanicalReduction>
    </actuator>
  </transmission>
  <transmission name="Revolute 17_tran">
    <type>transmission_interface/SimpleTransmission</type>
    <joint name="Revolute 17">
      <hardwareInterface>hardware_interface/EffortJointInterface</hardwareInterface>
    </joint>
    <actuator name="Revolute 17_actr">
      <hardwareInterface>hardware_interface/EffortJointInterface</hardwareInterface>
      <mechanicalReduction>1</mechanicalReduction>
    </actuator>
  </transmission>
  <transmission name="Revolute 18_tran">
    <type>transmission_interface/SimpleTransmission</type>
    <joint name="Revolute 18">
      <hardwareInterface>hardware_interface/EffortJointInterface</hardwareInterface>
    </joint>
    <actuator name="Revolute 18_actr">
      <hardwareInterface>hardware_interface/EffortJointInterface</hardwareInterface>
      <mechanicalReduction>1</mechanicalReduction>
    </actuator>
  </transmission>
  <transmission name="Revolute 19_tran">
    <type>transmission_interface/SimpleTransmission</type>
    <joint name="Revolute 19">
      <hardwareInterface>hardware_interface/EffortJointInterface</hardwareInterface>
    </joint>
    <actuator name="Revolute 19_actr">
      <hardwareInterface>hardware_interface/EffortJointInterface</hardwareInterface>
      <mechanicalReduction>1</mechanicalReduction>
    </actuator>
  </transmission>
  <transmission name="Revolute 20_tran">
    <type>transmission_interface/SimpleTransmission</type>
    <joint name="Revolute 20">
      <hardwareInterface>hardware_interface/EffortJointInterface</hardwareInterface>
    </joint>
    <actuator name="Revolute 20_actr">
      <hardwareInterface>hardware_interface/EffortJointInterface</hardwareInterface>
      <mechanicalReduction>1</mechanicalReduction>
    </actuator>
  </transmission>
  <transmission name="Revolute 21_tran">
    <type>transmission_interface/SimpleTransmission</type>
    <joint name="Revolute 21">
      <hardwareInterface>hardware_interface/EffortJointInterface</hardwareInterface>
    </joint>
    <actuator name="Revolute 21_actr">
      <hardwareInterface>hardware_interface/EffortJointInterface</hardwareInterface>
      <mechanicalReduction>1</mechanicalReduction>
    </actuator>
  </transmission>
  <transmission name="Revolute 22_tran">
    <type>transmission_interface/SimpleTransmission</type>
    <joint name="Revolute 22">
      <hardwareInterface>hardware_interface/EffortJointInterface</hardwareInterface>
    </joint>
    <actuator name="Revolute 22_actr">
      <hardwareInterface>hardware_interface/EffortJointInterface</hardwareInterface>
      <mechanicalReduction>1</mechanicalReduction>
    </actuator>
  </transmission>
  <transmission name="Revolute 23_tran">
    <type>transmission_interface/SimpleTransmission</type>
    <joint name="Revolute 23">
      <hardwareInterface>hardware_interface/EffortJointInterface</hardwareInterface>
    </joint>
    <actuator name="Revolute 23_actr">
      <hardwareInterface>hardware_interface/EffortJointInterface</hardwareInterface>
      <mechanicalReduction>1</mechanicalReduction>
    </actuator>
  </transmission>
  <transmission name="Revolute 24_tran">
    <type>transmission_interface/SimpleTransmission</type>
    <joint name="Revolute 24">
      <hardwareInterface>hardware_interface/EffortJointInterface</hardwareInterface>
    </joint>
    <actuator name="Revolute 24_actr">
      <hardwareInterface>hardware_interface/EffortJointInterface</hardwareInterface>
      <mechanicalReduction>1</mechanicalReduction>
    </actuator>
  </transmission>
  <transmission name="Revolute 25_tran">
    <type>transmission_interface/SimpleTransmission</type>
    <joint name="Revolute 25">
      <hardwareInterface>hardware_interface/EffortJointInterface</hardwareInterface>
    </joint>
    <actuator name="Revolute 25_actr">
      <hardwareInterface>hardware_interface/EffortJointInterface</hardwareInterface>
      <mechanicalReduction>1</mechanicalReduction>
    </actuator>
  </transmission>
  <transmission name="Revolute 26_tran">
    <type>transmission_interface/SimpleTransmission</type>
    <joint name="Revolute 26">
      <hardwareInterface>hardware_interface/EffortJointInterface</hardwareInterface>
    </joint>
    <actuator name="Revolute 26_actr">
      <hardwareInterface>hardware_interface/EffortJointInterface</hardwareInterface>
      <mechanicalReduction>1</mechanicalReduction>
    </actuator>
  </transmission>
  <transmission name="Revolute 27_tran">
    <type>transmission_interface/SimpleTransmission</type>
    <joint name="Revolute 27">
      <hardwareInterface>hardware_interface/EffortJointInterface</hardwareInterface>
    </joint>
    <actuator name="Revolute 27_actr">
      <hardwareInterface>hardware_interface/EffortJointInterface</hardwareInterface>
      <mechanicalReduction>1</mechanicalReduction>
    </actuator>
  </transmission>
  <transmission name="Revolute 28_tran">
    <type>transmission_interface/SimpleTransmission</type>
    <joint name="Revolute 28">
      <hardwareInterface>hardware_interface/EffortJointInterface</hardwareInterface>
    </joint>
    <actuator name="Revolute 28_actr">
      <hardwareInterface>hardware_interface/EffortJointInterface</hardwareInterface>
      <mechanicalReduction>1</mechanicalReduction>
    </actuator>
  </transmission>
  <transmission name="Revolute 29_tran">
    <type>transmission_interface/SimpleTransmission</type>
    <joint name="Revolute 29">
      <hardwareInterface>hardware_interface/EffortJointInterface</hardwareInterface>
    </joint>
    <actuator name="Revolute 29_actr">
      <hardwareInterface>hardware_interface/EffortJointInterface</hardwareInterface>
      <mechanicalReduction>1</mechanicalReduction>
    </actuator>
  </transmission>
  <transmission name="Revolute 30_tran">
    <type>transmission_interface/SimpleTransmission</type>
    <joint name="Revolute 30">
      <hardwareInterface>hardware_interface/EffortJointInterface</hardwareInterface>
    </joint>
    <actuator name="Revolute 30_actr">
      <hardwareInterface>hardware_interface/EffortJointInterface</hardwareInterface>
      <mechanicalReduction>1</mechanicalReduction>
    </actuator>
  </transmission>
  <transmission name="Revolute 31_tran">
    <type>transmission_interface/SimpleTransmission</type>
    <joint name="Revolute 31">
      <hardwareInterface>hardware_interface/EffortJointInterface</hardwareInterface>
    </joint>
    <actuator name="Revolute 31_actr">
      <hardwareInterface>hardware_interface/EffortJointInterface</hardwareInterface>
      <mechanicalReduction>1</mechanicalReduction>
    </actuator>
  </transmission>
  <transmission name="Revolute 32_tran">
    <type>transmission_interface/SimpleTransmission</type>
    <joint name="Revolute 32">
      <hardwareInterface>hardware_interface/EffortJointInterface</hardwareInterface>
    </joint>
    <actuator name="Revolute 32_actr">
      <hardwareInterface>hardware_interface/EffortJointInterface</hardwareInterface>
      <mechanicalReduction>1</mechanicalReduction>
    </actuator>
  </transmission>
  <transmission name="Revolute 33_tran">
    <type>transmission_interface/SimpleTransmission</type>
    <joint name="Revolute 33">
      <hardwareInterface>hardware_interface/EffortJointInterface</hardwareInterface>
    </joint>
    <actuator name="Revolute 33_actr">
      <hardwareInterface>hardware_interface/EffortJointInterface</hardwareInterface>
      <mechanicalReduction>1</mechanicalReduction>
    </actuator>
  </transmission>
  <transmission name="Revolute 34_tran">
    <type>transmission_interface/SimpleTransmission</type>
    <joint name="Revolute 34">
      <hardwareInterface>hardware_interface/EffortJointInterface</hardwareInterface>
    </joint>
    <actuator name="Revolute 34_actr">
      <hardwareInterface>hardware_interface/EffortJointInterface</hardwareInterface>
      <mechanicalReduction>1</mechanicalReduction>
    </actuator>
  </transmission>
  <transmission name="Revolute 35_tran">
    <type>transmission_interface/SimpleTransmission</type>
    <joint name="Revolute 35">
      <hardwareInterface>hardware_interface/EffortJointInterface</hardwareInterface>
    </joint>
    <actuator name="Revolute 35_actr">
      <hardwareInterface>hardware_interface/EffortJointInterface</hardwareInterface>
      <mechanicalReduction>1</mechanicalReduction>
    </actuator>
  </transmission>
  <transmission name="Revolute 36_tran">
    <type>transmission_interface/SimpleTransmission</type>
    <joint name="Revolute 36">
      <hardwareInterface>hardware_interface/EffortJointInterface</hardwareInterface>
    </joint>
    <actuator name="Revolute 36_actr">
      <hardwareInterface>hardware_interface/EffortJointInterface</hardwareInterface>
      <mechanicalReduction>1</mechanicalReduction>
    </actuator>
  </transmission>
  <gazebo>
    <plugin filename="libgazebo_ros_control.so" name="control"/>
  </gazebo>
  <gazebo reference="base_link">
    <material>Gazebo/black</material>
    <mu1>0.2</mu1>
    <mu2>0.2</mu2>
    <self_collide>true</self_collide>
    <gravity>true</gravity>
  </gazebo>
  <gazebo reference="wheel_hub_1">
    <material>Gazebo/black</material>
    <mu1>0.2</mu1>
    <mu2>0.2</mu2>
    <self_collide>true</self_collide>
  </gazebo>
  <gazebo reference="wheel_hub_2_1">
    <material>Gazebo/black</material>
    <mu1>0.2</mu1>
    <mu2>0.2</mu2>
    <self_collide>true</self_collide>
  </gazebo>
  <gazebo reference="wheel_hub_3_1">
    <material>Gazebo/black</material>
    <mu1>0.2</mu1>
    <mu2>0.2</mu2>
    <self_collide>true</self_collide>
  </gazebo>
  <gazebo reference="wheel_hub_4_1">
    <material>Gazebo/black</material>
    <mu1>0.2</mu1>
    <mu2>0.2</mu2>
    <self_collide>true</self_collide>
  </gazebo>
  <gazebo reference="roller_1_1">
    <material>Gazebo/black</material>
    <mu1>0.2</mu1>
    <mu2>0.2</mu2>
    <self_collide>true</self_collide>
  </gazebo>
  <gazebo reference="roller_1_2">
    <material>Gazebo/black</material>
    <mu1>0.2</mu1>
    <mu2>0.2</mu2>
    <self_collide>true</self_collide>
  </gazebo>
  <gazebo reference="roller_1_3">
    <material>Gazebo/black</material>
    <mu1>0.2</mu1>
    <mu2>0.2</mu2>
    <self_collide>true</self_collide>
  </gazebo>
  <gazebo reference="roller_1_4">
    <material>Gazebo/black</material>
    <mu1>0.2</mu1>
    <mu2>0.2</mu2>
    <self_collide>true</self_collide>
  </gazebo>
  <gazebo reference="roller_1_5">
    <material>Gazebo/black</material>
    <mu1>0.2</mu1>
    <mu2>0.2</mu2>
    <self_collide>true</self_collide>
  </gazebo>
  <gazebo reference="roller_1_6">
    <material>Gazebo/black</material>
    <mu1>0.2</mu1>
    <mu2>0.2</mu2>
    <self_collide>true</self_collide>
  </gazebo>
  <gazebo reference="roller_1_7">
    <material>Gazebo/black</material>
    <mu1>0.2</mu1>
    <mu2>0.2</mu2>
    <self_collide>true</self_collide>
  </gazebo>
  <gazebo reference="roller_1_8">
    <material>Gazebo/black</material>
    <mu1>0.2</mu1>
    <mu2>0.2</mu2>
    <self_collide>true</self_collide>
  </gazebo>
  <gazebo reference="roller_2_1">
    <material>Gazebo/black</material>
    <mu1>0.2</mu1>
    <mu2>0.2</mu2>
    <self_collide>true</self_collide>
  </gazebo>
  <gazebo reference="roller_2_2">
    <material>Gazebo/black</material>
    <mu1>0.2</mu1>
    <mu2>0.2</mu2>
    <self_collide>true</self_collide>
  </gazebo>
  <gazebo reference="roller_2_3">
    <material>Gazebo/black</material>
    <mu1>0.2</mu1>
    <mu2>0.2</mu2>
    <self_collide>true</self_collide>
  </gazebo>
  <gazebo reference="roller_2_4">
    <material>Gazebo/black</material>
    <mu1>0.2</mu1>
    <mu2>0.2</mu2>
    <self_collide>true</self_collide>
  </gazebo>
  <gazebo reference="roller_2_5">
    <material>Gazebo/black</material>
    <mu1>0.2</mu1>
    <mu2>0.2</mu2>
    <self_collide>true</self_collide>
  </gazebo>
  <gazebo reference="roller_2_6">
    <material>Gazebo/black</material>
    <mu1>0.2</mu1>
    <mu2>0.2</mu2>
    <self_collide>true</self_collide>
  </gazebo>
  <gazebo reference="roller_2_7">
    <material>Gazebo/black</material>
    <mu1>0.2</mu1>
    <mu2>0.2</mu2>
    <self_collide>true</self_collide>
  </gazebo>
  <gazebo reference="roller_2_8">
    <material>Gazebo/black</material>
    <mu1>0.2</mu1>
    <mu2>0.2</mu2>
    <self_collide>true</self_collide>
  </gazebo>
  <gazebo reference="roller_3_1">
    <material>Gazebo/black</material>
    <mu1>0.2</mu1>
    <mu2>0.2</mu2>
    <self_collide>true</self_collide>
  </gazebo>
  <gazebo reference="roller_3_2">
    <material>Gazebo/black</material>
    <mu1>0.2</mu1>
    <mu2>0.2</mu2>
    <self_collide>true</self_collide>
  </gazebo>
  <gazebo reference="roller_3_3">
    <material>Gazebo/black</material>
    <mu1>0.2</mu1>
    <mu2>0.2</mu2>
    <self_collide>true</self_collide>
  </gazebo>
  <gazebo reference="roller_3_4">
    <material>Gazebo/black</material>
    <mu1>0.2</mu1>
    <mu2>0.2</mu2>
    <self_collide>true</self_collide>
  </gazebo>
  <gazebo reference="roller_3_5">
    <material>Gazebo/black</material>
    <mu1>0.2</mu1>
    <mu2>0.2</mu2>
    <self_collide>true</self_collide>
  </gazebo>
  <gazebo reference="roller_3_6">
    <material>Gazebo/black</material>
    <mu1>0.2</mu1>
    <mu2>0.2</mu2>
    <self_collide>true</self_collide>
  </gazebo>
  <gazebo reference="roller_3_7">
    <material>Gazebo/black</material>
    <mu1>0.2</mu1>
    <mu2>0.2</mu2>
    <self_collide>true</self_collide>
  </gazebo>
  <gazebo reference="roller_3_8">
    <material>Gazebo/black</material>
    <mu1>0.2</mu1>
    <mu2>0.2</mu2>
    <self_collide>true</self_collide>
  </gazebo>
  <gazebo reference="roller_4_1">
    <material>Gazebo/black</material>
    <mu1>0.2</mu1>
    <mu2>0.2</mu2>
    <self_collide>true</self_collide>
  </gazebo>
  <gazebo reference="roller_4_2">
    <material>Gazebo/black</material>
    <mu1>0.2</mu1>
    <mu2>0.2</mu2>
    <self_collide>true</self_collide>
  </gazebo>
  <gazebo reference="roller_4_3">
    <material>Gazebo/black</material>
    <mu1>0.2</mu1>
    <mu2>0.2</mu2>
    <self_collide>true</self_collide>
  </gazebo>
  <gazebo reference="roller_4_4">
    <material>Gazebo/black</material>
    <mu1>0.2</mu1>
    <mu2>0.2</mu2>
    <self_collide>true</self_collide>
  </gazebo>
  <gazebo reference="roller_4_5">
    <material>Gazebo/black</material>
    <mu1>0.2</mu1>
    <mu2>0.2</mu2>
    <self_collide>true</self_collide>
  </gazebo>
  <gazebo reference="roller_4_6">
    <material>Gazebo/black</material>
    <mu1>0.2</mu1>
    <mu2>0.2</mu2>
    <self_collide>true</self_collide>
  </gazebo>
  <gazebo reference="roller_4_7">
    <material>Gazebo/black</material>
    <mu1>0.2</mu1>
    <mu2>0.2</mu2>
    <self_collide>true</self_collide>
  </gazebo>
  <gazebo reference="roller_4_8">
    <material>Gazebo/black</material>
    <mu1>0.2</mu1>
    <mu2>0.2</mu2>
    <self_collide>true</self_collide>
  </gazebo>
  <gazebo reference="imu_1">
    <material>Gazebo/black</material>
    <mu1>0.2</mu1>
    <mu2>0.2</mu2>
    <self_collide>true</self_collide>
  </gazebo>
  <gazebo reference="Camera_1">
    <material>Gazebo/black</material>
    <mu1>0.2</mu1>
    <mu2>0.2</mu2>
    <self_collide>true</self_collide>
  </gazebo>
  <gazebo reference="Intel_Realsense_RPLIDAR_1">
    <material>Gazebo/black</material>
    <mu1>0.2</mu1>
    <mu2>0.2</mu2>
    <self_collide>true</self_collide>
  </gazebo>
  <link name="base_link">
    <inertial>
      <origin rpy="0 0 0" xyz="-0.00634522824548986 -0.00013537462402944816 0.06199171397610347"/>
      <mass value="5.451942477570936"/>
      <inertia ixx="0.198344" ixy="-0.000126" ixz="9.8e-05" iyy="0.258519" iyz="3e-06" izz="0.440587"/>
    </inertial>
    <visual>
      <origin rpy="0 0 0" xyz="0 0 0"/>
      <geometry>
        <mesh filename="/home/ilabs/Desktop/amr_ws/src/amr_ust_description/meshes/base_link.stl" scale="0.001 0.001 0.001"/>
      </geometry>
      <material name="yellow"/>
    </visual>
    <collision>
      <origin rpy="0 0 0" xyz="0 0 0"/>
      <geometry>
        <mesh filename="/home/ilabs/Desktop/amr_ws/src/amr_ust_description/meshes/base_link.stl" scale="0.001 0.001 0.001"/>
      </geometry>
    </collision>
  </link>
  <link name="wheel_hub_1">
    <inertial>
      <origin rpy="0 0 0" xyz="-2.639485790456586e-05 0.020563742043534228 -3.311900293296449e-05"/>
      <mass value="0.7547170756703072"/>
      <inertia ixx="0.000439" ixy="-1e-06" ixz="0.0" iyy="0.000283" iyz="-1e-06" izz="0.000439"/>
    </inertial>
    <visual>
      <origin rpy="0 0 0" xyz="-0.244627 -0.278967 -0.032976"/>
      <geometry>
        <mesh filename="/home/ilabs/Desktop/amr_ws/src/amr_ust_description/meshes/wheel_hub_1.stl" scale="0.001 0.001 0.001"/>
      </geometry>
      <material name="silver"/>
    </visual>
    <collision>
      <origin rpy="0 0 0" xyz="-0.244627 -0.278967 -0.032976"/>
      <geometry>
        <mesh filename="/home/ilabs/Desktop/amr_ws/src/amr_ust_description/meshes/wheel_hub_1.stl" scale="0.001 0.001 0.001"/>
      </geometry>
    </collision>
  </link>
  <link name="wheel_hub_2_1">
    <inertial>
      <origin rpy="0 0 0" xyz="-2.6216982503601827e-05 -0.020564086928370973 -3.3116504283184356e-05"/>
      <mass value="0.7547170756701437"/>
      <inertia ixx="0.000439" ixy="1e-06" ixz="0.0" iyy="0.000283" iyz="1e-06" izz="0.000439"/>
    </inertial>
    <visual>
      <origin rpy="0 0 0" xyz="-0.244627 0.279033 -0.032976"/>
      <geometry>
        <mesh filename="/home/ilabs/Desktop/amr_ws/src/amr_ust_description/meshes/wheel_hub_2_1.stl" scale="0.001 0.001 0.001"/>
      </geometry>
      <material name="silver"/>
    </visual>
    <collision>
      <origin rpy="0 0 0" xyz="-0.244627 0.279033 -0.032976"/>
      <geometry>
        <mesh filename="/home/ilabs/Desktop/amr_ws/src/amr_ust_description/meshes/wheel_hub_2_1.stl" scale="0.001 0.001 0.001"/>
      </geometry>
    </collision>
  </link>
  <link name="wheel_hub_3_1">
    <inertial>
      <origin rpy="0 0 0" xyz="-3.318509563710048e-05 0.020563634860040703 -2.6215654236647068e-05"/>
      <mass value="0.7547170756701448"/>
      <inertia ixx="0.000439" ixy="-1e-06" ixz="0.0" iyy="0.000283" iyz="-1e-06" izz="0.000439"/>
    </inertial>
    <visual>
      <origin rpy="0 0 0" xyz="0.268017 -0.278467 -0.032976"/>
      <geometry>
        <mesh filename="/home/ilabs/Desktop/amr_ws/src/amr_ust_description/meshes/wheel_hub_3_1.stl" scale="0.001 0.001 0.001"/>
      </geometry>
      <material name="silver"/>
    </visual>
    <collision>
      <origin rpy="0 0 0" xyz="0.268017 -0.278467 -0.032976"/>
      <geometry>
        <mesh filename="/home/ilabs/Desktop/amr_ws/src/amr_ust_description/meshes/wheel_hub_3_1.stl" scale="0.001 0.001 0.001"/>
      </geometry>
    </collision>
  </link>
  <link name="wheel_hub_4_1">
    <inertial>
      <origin rpy="0 0 0" xyz="-2.6265710571016232e-05 -0.020564051680927398 3.311435024339754e-05"/>
      <mass value="0.7547170756759828"/>
      <inertia ixx="0.000439" ixy="1e-06" ixz="-0.0" iyy="0.000283" iyz="-1e-06" izz="0.000439"/>
    </inertial>
    <visual>
      <origin rpy="0 0 0" xyz="0.268017 0.279533 -0.032976"/>
      <geometry>
        <mesh filename="/home/ilabs/Desktop/amr_ws/src/amr_ust_description/meshes/wheel_hub_4_1.stl" scale="0.001 0.001 0.001"/>
      </geometry>
      <material name="silver"/>
    </visual>
    <collision>
      <origin rpy="0 0 0" xyz="0.268017 0.279533 -0.032976"/>
      <geometry>
        <mesh filename="/home/ilabs/Desktop/amr_ws/src/amr_ust_description/meshes/wheel_hub_4_1.stl" scale="0.001 0.001 0.001"/>
      </geometry>
    </collision>
  </link>
  <link name="roller_1_1">
    <inertial>
      <origin rpy="0 0 0" xyz="0.017543151467361517 -0.01754284500297798 -1.0594511379302674e-11"/>
      <mass value="0.10437828701390915"/>
      <inertia ixx="1.3e-05" ixy="8e-06" ixz="-0.0" iyy="1.3e-05" iyz="-0.0" izz="2.1e-05"/>
    </inertial>
    <visual>
      <origin rpy="0 0 0" xyz="-0.227018 -0.323284 -0.070476"/>
      <geometry>
        <mesh filename="/home/ilabs/Desktop/amr_ws/src/amr_ust_description/meshes/roller_1_1.stl" scale="0.001 0.001 0.001"/>
      </geometry>
      <material name="black"/>
    </visual>
    <collision>
      <origin rpy="0 0 0" xyz="-0.227018 -0.323284 -0.070476"/>
      <geometry>
        <mesh filename="/home/ilabs/Desktop/amr_ws/src/amr_ust_description/meshes/roller_1_1.stl" scale="0.001 0.001 0.001"/>
      </geometry>
    </collision>
  </link>
  <link name="roller_1_2">
    <inertial>
      <origin rpy="0 0 0" xyz="0.012404932084268683 -0.01754284500057013 -0.012404958556342202"/>
      <mass value="0.10437828701390915"/>
      <inertia ixx="1.7e-05" ixy="6e-06" ixz="4e-06" iyy="1.3e-05" iyz="-6e-06" izz="1.7e-05"/>
    </inertial>
    <visual>
      <origin rpy="0 0 0" xyz="-0.258692 -0.323284 -0.071944"/>
      <geometry>
        <mesh filename="/home/ilabs/Desktop/amr_ws/src/amr_ust_description/meshes/roller_1_2.stl" scale="0.001 0.001 0.001"/>
      </geometry>
      <material name="black"/>
    </visual>
    <collision>
      <origin rpy="0 0 0" xyz="-0.258692 -0.323284 -0.071944"/>
      <geometry>
        <mesh filename="/home/ilabs/Desktop/amr_ws/src/amr_ust_description/meshes/roller_1_2.stl" scale="0.001 0.001 0.001"/>
      </geometry>
    </collision>
  </link>
  <link name="roller_1_3">
    <inertial>
      <origin rpy="0 0 0" xyz="-3.50492340150943e-08 -0.017542844997298468 -0.017543186524848743"/>
      <mass value="0.10437828701390915"/>
      <inertia ixx="2.1e-05" ixy="0.0" ixz="-0.0" iyy="1.3e-05" iyz="-8e-06" izz="1.3e-05"/>
    </inertial>
    <visual>
      <origin rpy="0 0 0" xyz="-0.282127 -0.323284 -0.050585"/>
      <geometry>
        <mesh filename="/home/ilabs/Desktop/amr_ws/src/amr_ust_description/meshes/roller_1_3.stl" scale="0.001 0.001 0.001"/>
      </geometry>
      <material name="black"/>
    </visual>
    <collision>
      <origin rpy="0 0 0" xyz="-0.282127 -0.323284 -0.050585"/>
      <geometry>
        <mesh filename="/home/ilabs/Desktop/amr_ws/src/amr_ust_description/meshes/roller_1_3.stl" scale="0.001 0.001 0.001"/>
      </geometry>
    </collision>
  </link>
  <link name="roller_1_4">
    <inertial>
      <origin rpy="0 0 0" xyz="-0.012404993591602409 -0.017542844994042683 -0.012404967140717836"/>
      <mass value="0.10437828701390915"/>
      <inertia ixx="1.7e-05" ixy="-6e-06" ixz="-4e-06" iyy="1.3e-05" iyz="-6e-06" izz="1.7e-05"/>
    </inertial>
    <visual>
      <origin rpy="0 0 0" xyz="-0.283595 -0.323284 -0.018911"/>
      <geometry>
        <mesh filename="/home/ilabs/Desktop/amr_ws/src/amr_ust_description/meshes/roller_1_4.stl" scale="0.001 0.001 0.001"/>
      </geometry>
      <material name="black"/>
    </visual>
    <collision>
      <origin rpy="0 0 0" xyz="-0.283595 -0.323284 -0.018911"/>
      <geometry>
        <mesh filename="/home/ilabs/Desktop/amr_ws/src/amr_ust_description/meshes/roller_1_4.stl" scale="0.001 0.001 0.001"/>
      </geometry>
    </collision>
  </link>
  <link name="roller_1_5">
    <inertial>
      <origin rpy="0 0 0" xyz="-0.017543221561155925 -0.017542844991662976 -1.0594235558269993e-11"/>
      <mass value="0.10437828701390915"/>
      <inertia ixx="1.3e-05" ixy="-8e-06" ixz="-0.0" iyy="1.3e-05" iyz="0.0" izz="2.1e-05"/>
    </inertial>
    <visual>
      <origin rpy="0 0 0" xyz="-0.262236 -0.323284 0.004524"/>
      <geometry>
        <mesh filename="/home/ilabs/Desktop/amr_ws/src/amr_ust_description/meshes/roller_1_5.stl" scale="0.001 0.001 0.001"/>
      </geometry>
      <material name="black"/>
    </visual>
    <collision>
      <origin rpy="0 0 0" xyz="-0.262236 -0.323284 0.004524"/>
      <geometry>
        <mesh filename="/home/ilabs/Desktop/amr_ws/src/amr_ust_description/meshes/roller_1_5.stl" scale="0.001 0.001 0.001"/>
      </geometry>
    </collision>
  </link>
  <link name="roller_1_6">
    <inertial>
      <origin rpy="0 0 0" xyz="-0.012405002180593483 -0.017542844994079543 0.012404958530537124"/>
      <mass value="0.10437828701390915"/>
      <inertia ixx="1.7e-05" ixy="-6e-06" ixz="4e-06" iyy="1.3e-05" iyz="6e-06" izz="1.7e-05"/>
    </inertial>
    <visual>
      <origin rpy="0 0 0" xyz="-0.230562 -0.323284 0.005992"/>
      <geometry>
        <mesh filename="/home/ilabs/Desktop/amr_ws/src/amr_ust_description/meshes/roller_1_6.stl" scale="0.001 0.001 0.001"/>
      </geometry>
      <material name="black"/>
    </visual>
    <collision>
      <origin rpy="0 0 0" xyz="-0.230562 -0.323284 0.005992"/>
      <geometry>
        <mesh filename="/home/ilabs/Desktop/amr_ws/src/amr_ust_description/meshes/roller_1_6.stl" scale="0.001 0.001 0.001"/>
      </geometry>
    </collision>
  </link>
  <link name="roller_1_7">
    <inertial>
      <origin rpy="0 0 0" xyz="-3.5049233293449333e-08 -0.01754284499735176 0.017543186503658992"/>
      <mass value="0.10437828701390915"/>
      <inertia ixx="2.1e-05" ixy="-0.0" ixz="-0.0" iyy="1.3e-05" iyz="8e-06" izz="1.3e-05"/>
    </inertial>
    <visual>
      <origin rpy="0 0 0" xyz="-0.207127 -0.323284 -0.015367"/>
      <geometry>
        <mesh filename="/home/ilabs/Desktop/amr_ws/src/amr_ust_description/meshes/roller_1_7.stl" scale="0.001 0.001 0.001"/>
      </geometry>
      <material name="black"/>
    </visual>
    <collision>
      <origin rpy="0 0 0" xyz="-0.207127 -0.323284 -0.015367"/>
      <geometry>
        <mesh filename="/home/ilabs/Desktop/amr_ws/src/amr_ust_description/meshes/roller_1_7.stl" scale="0.001 0.001 0.001"/>
      </geometry>
    </collision>
  </link>
  <link name="roller_1_8">
    <inertial>
      <origin rpy="0 0 0" xyz="0.01240492349527686 -0.017542845000608598 0.012404967124144517"/>
      <mass value="0.10437828701390915"/>
      <inertia ixx="1.7e-05" ixy="6e-06" ixz="-4e-06" iyy="1.3e-05" iyz="6e-06" izz="1.7e-05"/>
    </inertial>
    <visual>
      <origin rpy="0 0 0" xyz="-0.205659 -0.323284 -0.047041"/>
      <geometry>
        <mesh filename="/home/ilabs/Desktop/amr_ws/src/amr_ust_description/meshes/roller_1_8.stl" scale="0.001 0.001 0.001"/>
      </geometry>
      <material name="black"/>
    </visual>
    <collision>
      <origin rpy="0 0 0" xyz="-0.205659 -0.323284 -0.047041"/>
      <geometry>
        <mesh filename="/home/ilabs/Desktop/amr_ws/src/amr_ust_description/meshes/roller_1_8.stl" scale="0.001 0.001 0.001"/>
      </geometry>
    </collision>
  </link>
  <link name="roller_2_1">
    <inertial>
      <origin rpy="0 0 0" xyz="0.01262866495368864 0.017859997380744397 -0.01262869142546618"/>
      <mass value="0.1043782870139091"/>
      <inertia ixx="1.7e-05" ixy="-6e-06" ixz="4e-06" iyy="1.3e-05" iyz="6e-06" izz="1.7e-05"/>
    </inertial>
    <visual>
      <origin rpy="0 0 0" xyz="-0.258692 0.323351 -0.071944"/>
      <geometry>
        <mesh filename="/home/ilabs/Desktop/amr_ws/src/amr_ust_description/meshes/roller_2_1.stl" scale="0.001 0.001 0.001"/>
      </geometry>
      <material name="black"/>
    </visual>
    <collision>
      <origin rpy="0 0 0" xyz="-0.258692 0.323351 -0.071944"/>
      <geometry>
        <mesh filename="/home/ilabs/Desktop/amr_ws/src/amr_ust_description/meshes/roller_2_1.stl" scale="0.001 0.001 0.001"/>
      </geometry>
    </collision>
  </link>
  <link name="roller_2_2">
    <inertial>
      <origin rpy="0 0 0" xyz="0.017859557525525316 0.017859997383116 -1.0596287736142074e-11"/>
      <mass value="0.1043782870139091"/>
      <inertia ixx="1.3e-05" ixy="-8e-06" ixz="-0.0" iyy="1.3e-05" iyz="0.0" izz="2.1e-05"/>
    </inertial>
    <visual>
      <origin rpy="0 0 0" xyz="-0.227018 0.323351 -0.070476"/>
      <geometry>
        <mesh filename="/home/ilabs/Desktop/amr_ws/src/amr_ust_description/meshes/roller_2_2.stl" scale="0.001 0.001 0.001"/>
      </geometry>
      <material name="black"/>
    </visual>
    <collision>
      <origin rpy="0 0 0" xyz="-0.227018 0.323351 -0.070476"/>
      <geometry>
        <mesh filename="/home/ilabs/Desktop/amr_ws/src/amr_ust_description/meshes/roller_2_2.stl" scale="0.001 0.001 0.001"/>
      </geometry>
    </collision>
  </link>
  <link name="roller_2_3">
    <inertial>
      <origin rpy="0 0 0" xyz="-3.504893653083485e-08 0.017859997377485448 -0.017859592582711817"/>
      <mass value="0.1043782870139091"/>
      <inertia ixx="2.1e-05" ixy="-0.0" ixz="-0.0" iyy="1.3e-05" iyz="8e-06" izz="1.3e-05"/>
    </inertial>
    <visual>
      <origin rpy="0 0 0" xyz="-0.282127 0.323351 -0.050585"/>
      <geometry>
        <mesh filename="/home/ilabs/Desktop/amr_ws/src/amr_ust_description/meshes/roller_2_3.stl" scale="0.001 0.001 0.001"/>
      </geometry>
      <material name="black"/>
    </visual>
    <collision>
      <origin rpy="0 0 0" xyz="-0.282127 0.323351 -0.050585"/>
      <geometry>
        <mesh filename="/home/ilabs/Desktop/amr_ws/src/amr_ust_description/meshes/roller_2_3.stl" scale="0.001 0.001 0.001"/>
      </geometry>
    </collision>
  </link>
  <link name="roller_2_4">
    <inertial>
      <origin rpy="0 0 0" xyz="-0.012628726460427897 0.017859997374215952 -0.012628700009841565"/>
      <mass value="0.1043782870139091"/>
      <inertia ixx="1.7e-05" ixy="6e-06" ixz="-4e-06" iyy="1.3e-05" iyz="6e-06" izz="1.7e-05"/>
    </inertial>
    <visual>
      <origin rpy="0 0 0" xyz="-0.283595 0.323351 -0.018911"/>
      <geometry>
        <mesh filename="/home/ilabs/Desktop/amr_ws/src/amr_ust_description/meshes/roller_2_4.stl" scale="0.001 0.001 0.001"/>
      </geometry>
      <material name="black"/>
    </visual>
    <collision>
      <origin rpy="0 0 0" xyz="-0.283595 0.323351 -0.018911"/>
      <geometry>
        <mesh filename="/home/ilabs/Desktop/amr_ws/src/amr_ust_description/meshes/roller_2_4.stl" scale="0.001 0.001 0.001"/>
      </geometry>
    </collision>
  </link>
  <link name="roller_2_5">
    <inertial>
      <origin rpy="0 0 0" xyz="-0.017859627618709933 0.017859997371814595 -1.0596117733241428e-11"/>
      <mass value="0.1043782870139091"/>
      <inertia ixx="1.3e-05" ixy="8e-06" ixz="-0.0" iyy="1.3e-05" iyz="-0.0" izz="2.1e-05"/>
    </inertial>
    <visual>
      <origin rpy="0 0 0" xyz="-0.262236 0.323351 0.004524"/>
      <geometry>
        <mesh filename="/home/ilabs/Desktop/amr_ws/src/amr_ust_description/meshes/roller_2_5.stl" scale="0.001 0.001 0.001"/>
      </geometry>
      <material name="black"/>
    </visual>
    <collision>
      <origin rpy="0 0 0" xyz="-0.262236 0.323351 0.004524"/>
      <geometry>
        <mesh filename="/home/ilabs/Desktop/amr_ws/src/amr_ust_description/meshes/roller_2_5.stl" scale="0.001 0.001 0.001"/>
      </geometry>
    </collision>
  </link>
  <link name="roller_2_6">
    <inertial>
      <origin rpy="0 0 0" xyz="-0.012628735049418499 0.017859997374192915 0.012628691399658758"/>
      <mass value="0.1043782870139091"/>
      <inertia ixx="1.7e-05" ixy="6e-06" ixz="4e-06" iyy="1.3e-05" iyz="-6e-06" izz="1.7e-05"/>
    </inertial>
    <visual>
      <origin rpy="0 0 0" xyz="-0.230562 0.323351 0.005992"/>
      <geometry>
        <mesh filename="/home/ilabs/Desktop/amr_ws/src/amr_ust_description/meshes/roller_2_6.stl" scale="0.001 0.001 0.001"/>
      </geometry>
      <material name="black"/>
    </visual>
    <collision>
      <origin rpy="0 0 0" xyz="-0.230562 0.323351 0.005992"/>
      <geometry>
        <mesh filename="/home/ilabs/Desktop/amr_ws/src/amr_ust_description/meshes/roller_2_6.stl" scale="0.001 0.001 0.001"/>
      </geometry>
    </collision>
  </link>
  <link name="roller_2_7">
    <inertial>
      <origin rpy="0 0 0" xyz="-3.5048936197767944e-08 0.017859997377449754 0.01785959256151852"/>
      <mass value="0.1043782870139091"/>
      <inertia ixx="2.1e-05" ixy="0.0" ixz="-0.0" iyy="1.3e-05" iyz="-8e-06" izz="1.3e-05"/>
    </inertial>
    <visual>
      <origin rpy="0 0 0" xyz="-0.207127 0.323351 -0.015367"/>
      <geometry>
        <mesh filename="/home/ilabs/Desktop/amr_ws/src/amr_ust_description/meshes/roller_2_7.stl" scale="0.001 0.001 0.001"/>
      </geometry>
      <material name="black"/>
    </visual>
    <collision>
      <origin rpy="0 0 0" xyz="-0.207127 0.323351 -0.015367"/>
      <geometry>
        <mesh filename="/home/ilabs/Desktop/amr_ws/src/amr_ust_description/meshes/roller_2_7.stl" scale="0.001 0.001 0.001"/>
      </geometry>
    </collision>
  </link>
  <link name="roller_2_8">
    <inertial>
      <origin rpy="0 0 0" xyz="0.012628656364696678 0.01785999738071853 0.012628699993264443"/>
      <mass value="0.1043782870139091"/>
      <inertia ixx="1.7e-05" ixy="-6e-06" ixz="-4e-06" iyy="1.3e-05" iyz="-6e-06" izz="1.7e-05"/>
    </inertial>
    <visual>
      <origin rpy="0 0 0" xyz="-0.205659 0.323351 -0.047041"/>
      <geometry>
        <mesh filename="/home/ilabs/Desktop/amr_ws/src/amr_ust_description/meshes/roller_2_8.stl" scale="0.001 0.001 0.001"/>
      </geometry>
      <material name="black"/>
    </visual>
    <collision>
      <origin rpy="0 0 0" xyz="-0.205659 0.323351 -0.047041"/>
      <geometry>
        <mesh filename="/home/ilabs/Desktop/amr_ws/src/amr_ust_description/meshes/roller_2_8.stl" scale="0.001 0.001 0.001"/>
      </geometry>
    </collision>
  </link>
  <link name="roller_3_1">
    <inertial>
      <origin rpy="0 0 0" xyz="-0.01754322156300464 -0.01754284498951264 -1.538191796157662e-10"/>
      <mass value="0.10437828701391214"/>
      <inertia ixx="1.3e-05" ixy="-8e-06" ixz="-0.0" iyy="1.3e-05" iyz="0.0" izz="2.1e-05"/>
    </inertial>
    <visual>
      <origin rpy="0 0 0" xyz="0.250408 -0.322784 -0.070476"/>
      <geometry>
        <mesh filename="/home/ilabs/Desktop/amr_ws/src/amr_ust_description/meshes/roller_3_1.stl" scale="0.001 0.001 0.001"/>
      </geometry>
      <material name="black"/>
    </visual>
    <collision>
      <origin rpy="0 0 0" xyz="0.250408 -0.322784 -0.070476"/>
      <geometry>
        <mesh filename="/home/ilabs/Desktop/amr_ws/src/amr_ust_description/meshes/roller_3_1.stl" scale="0.001 0.001 0.001"/>
      </geometry>
    </collision>
  </link>
  <link name="roller_3_2">
    <inertial>
      <origin rpy="0 0 0" xyz="-0.012405002182447389 -0.017542844991918383 -0.012404958694950195"/>
      <mass value="0.10437828701391214"/>
      <inertia ixx="1.7e-05" ixy="-6e-06" ixz="-4e-06" iyy="1.3e-05" iyz="-6e-06" izz="1.7e-05"/>
    </inertial>
    <visual>
      <origin rpy="0 0 0" xyz="0.282082 -0.322784 -0.071944"/>
      <geometry>
        <mesh filename="/home/ilabs/Desktop/amr_ws/src/amr_ust_description/meshes/roller_3_2.stl" scale="0.001 0.001 0.001"/>
      </geometry>
      <material name="black"/>
    </visual>
    <collision>
      <origin rpy="0 0 0" xyz="0.282082 -0.322784 -0.071944"/>
      <geometry>
        <mesh filename="/home/ilabs/Desktop/amr_ws/src/amr_ust_description/meshes/roller_3_2.stl" scale="0.001 0.001 0.001"/>
      </geometry>
    </collision>
  </link>
  <link name="roller_3_3">
    <inertial>
      <origin rpy="0 0 0" xyz="-3.5051090030435716e-08 -0.017542844995186935 -0.017543186668072128"/>
      <mass value="0.10437828701391214"/>
      <inertia ixx="2.1e-05" ixy="0.0" ixz="-0.0" iyy="1.3e-05" iyz="-8e-06" izz="1.3e-05"/>
    </inertial>
    <visual>
      <origin rpy="0 0 0" xyz="0.305517 -0.322784 -0.050585"/>
      <geometry>
        <mesh filename="/home/ilabs/Desktop/amr_ws/src/amr_ust_description/meshes/roller_3_3.stl" scale="0.001 0.001 0.001"/>
      </geometry>
      <material name="black"/>
    </visual>
    <collision>
      <origin rpy="0 0 0" xyz="0.305517 -0.322784 -0.050585"/>
      <geometry>
        <mesh filename="/home/ilabs/Desktop/amr_ws/src/amr_ust_description/meshes/roller_3_3.stl" scale="0.001 0.001 0.001"/>
      </geometry>
    </collision>
  </link>
  <link name="roller_3_4">
    <inertial>
      <origin rpy="0 0 0" xyz="0.012404923493422093 -0.01754284499844483 -0.012404967288556236"/>
      <mass value="0.10437828701391214"/>
      <inertia ixx="1.7e-05" ixy="6e-06" ixz="4e-06" iyy="1.3e-05" iyz="-6e-06" izz="1.7e-05"/>
    </inertial>
    <visual>
      <origin rpy="0 0 0" xyz="0.306985 -0.322784 -0.018911"/>
      <geometry>
        <mesh filename="/home/ilabs/Desktop/amr_ws/src/amr_ust_description/meshes/roller_3_4.stl" scale="0.001 0.001 0.001"/>
      </geometry>
      <material name="black"/>
    </visual>
    <collision>
      <origin rpy="0 0 0" xyz="0.306985 -0.322784 -0.018911"/>
      <geometry>
        <mesh filename="/home/ilabs/Desktop/amr_ws/src/amr_ust_description/meshes/roller_3_4.stl" scale="0.001 0.001 0.001"/>
      </geometry>
    </collision>
  </link>
  <link name="roller_3_5">
    <inertial>
      <origin rpy="0 0 0" xyz="0.017543151465506057 -0.01754284500082315 -1.5381812143444584e-10"/>
      <mass value="0.10437828701391214"/>
      <inertia ixx="1.3e-05" ixy="8e-06" ixz="-0.0" iyy="1.3e-05" iyz="-0.0" izz="2.1e-05"/>
    </inertial>
    <visual>
      <origin rpy="0 0 0" xyz="0.285626 -0.322784 0.004524"/>
      <geometry>
        <mesh filename="/home/ilabs/Desktop/amr_ws/src/amr_ust_description/meshes/roller_3_5.stl" scale="0.001 0.001 0.001"/>
      </geometry>
      <material name="black"/>
    </visual>
    <collision>
      <origin rpy="0 0 0" xyz="0.285626 -0.322784 0.004524"/>
      <geometry>
        <mesh filename="/home/ilabs/Desktop/amr_ws/src/amr_ust_description/meshes/roller_3_5.stl" scale="0.001 0.001 0.001"/>
      </geometry>
    </collision>
  </link>
  <link name="roller_3_6">
    <inertial>
      <origin rpy="0 0 0" xyz="0.01240493208241214 -0.017542844998421847 0.012404958391928143"/>
      <mass value="0.10437828701391214"/>
      <inertia ixx="1.7e-05" ixy="6e-06" ixz="-4e-06" iyy="1.3e-05" iyz="6e-06" izz="1.7e-05"/>
    </inertial>
    <visual>
      <origin rpy="0 0 0" xyz="0.253952 -0.322784 0.005992"/>
      <geometry>
        <mesh filename="/home/ilabs/Desktop/amr_ws/src/amr_ust_description/meshes/roller_3_6.stl" scale="0.001 0.001 0.001"/>
      </geometry>
      <material name="black"/>
    </visual>
    <collision>
      <origin rpy="0 0 0" xyz="0.253952 -0.322784 0.005992"/>
      <geometry>
        <mesh filename="/home/ilabs/Desktop/amr_ws/src/amr_ust_description/meshes/roller_3_6.stl" scale="0.001 0.001 0.001"/>
      </geometry>
    </collision>
  </link>
  <link name="roller_3_7">
    <inertial>
      <origin rpy="0 0 0" xyz="-0.012404993593458591 -0.017542844991894402 0.012404966976303597"/>
      <mass value="0.10437828701391214"/>
      <inertia ixx="1.7e-05" ixy="-6e-06" ixz="4e-06" iyy="1.3e-05" iyz="6e-06" izz="1.7e-05"/>
    </inertial>
    <visual>
      <origin rpy="0 0 0" xyz="0.229049 -0.322784 -0.047041"/>
      <geometry>
        <mesh filename="/home/ilabs/Desktop/amr_ws/src/amr_ust_description/meshes/roller_3_7.stl" scale="0.001 0.001 0.001"/>
      </geometry>
      <material name="black"/>
    </visual>
    <collision>
      <origin rpy="0 0 0" xyz="0.229049 -0.322784 -0.047041"/>
      <geometry>
        <mesh filename="/home/ilabs/Desktop/amr_ws/src/amr_ust_description/meshes/roller_3_7.stl" scale="0.001 0.001 0.001"/>
      </geometry>
    </collision>
  </link>
  <link name="roller_3_8">
    <inertial>
      <origin rpy="0 0 0" xyz="-3.505108961410208e-08 -0.01754284499515346 0.017543186360434393"/>
      <mass value="0.10437828701391214"/>
      <inertia ixx="2.1e-05" ixy="-0.0" ixz="-0.0" iyy="1.3e-05" iyz="8e-06" izz="1.3e-05"/>
    </inertial>
    <visual>
      <origin rpy="0 0 0" xyz="0.230517 -0.322784 -0.015367"/>
      <geometry>
        <mesh filename="/home/ilabs/Desktop/amr_ws/src/amr_ust_description/meshes/roller_3_8.stl" scale="0.001 0.001 0.001"/>
      </geometry>
      <material name="black"/>
    </visual>
    <collision>
      <origin rpy="0 0 0" xyz="0.230517 -0.322784 -0.015367"/>
      <geometry>
        <mesh filename="/home/ilabs/Desktop/amr_ws/src/amr_ust_description/meshes/roller_3_8.stl" scale="0.001 0.001 0.001"/>
      </geometry>
    </collision>
  </link>
  <link name="roller_4_1">
    <inertial>
      <origin rpy="0 0 0" xyz="-0.01785962762313098 0.017859997371392433 -1.4103307410806565e-10"/>
      <mass value="0.10437828701391043"/>
      <inertia ixx="1.3e-05" ixy="8e-06" ixz="-0.0" iyy="1.3e-05" iyz="-0.0" izz="2.1e-05"/>
    </inertial>
    <visual>
      <origin rpy="0 0 0" xyz="0.250408 0.323851 -0.070476"/>
      <geometry>
        <mesh filename="/home/ilabs/Desktop/amr_ws/src/amr_ust_description/meshes/roller_4_1.stl" scale="0.001 0.001 0.001"/>
      </geometry>
      <material name="black"/>
    </visual>
    <collision>
      <origin rpy="0 0 0" xyz="0.250408 0.323851 -0.070476"/>
      <geometry>
        <mesh filename="/home/ilabs/Desktop/amr_ws/src/amr_ust_description/meshes/roller_4_1.stl" scale="0.001 0.001 0.001"/>
      </geometry>
    </collision>
  </link>
  <link name="roller_4_2">
    <inertial>
      <origin rpy="0 0 0" xyz="-0.012628735053839935 0.01785999737376276 -0.012628691551287312"/>
      <mass value="0.10437828701391043"/>
      <inertia ixx="1.7e-05" ixy="6e-06" ixz="-4e-06" iyy="1.3e-05" iyz="6e-06" izz="1.7e-05"/>
    </inertial>
    <visual>
      <origin rpy="0 0 0" xyz="0.282082 0.323851 -0.071944"/>
      <geometry>
        <mesh filename="/home/ilabs/Desktop/amr_ws/src/amr_ust_description/meshes/roller_4_2.stl" scale="0.001 0.001 0.001"/>
      </geometry>
      <material name="black"/>
    </visual>
    <collision>
      <origin rpy="0 0 0" xyz="0.282082 0.323851 -0.071944"/>
      <geometry>
        <mesh filename="/home/ilabs/Desktop/amr_ws/src/amr_ust_description/meshes/roller_4_2.stl" scale="0.001 0.001 0.001"/>
      </geometry>
    </collision>
  </link>
  <link name="roller_4_3">
    <inertial>
      <origin rpy="0 0 0" xyz="-3.5053357272385455e-08 0.017859997376992898 -0.017859592713148985"/>
      <mass value="0.10437828701391043"/>
      <inertia ixx="2.1e-05" ixy="-0.0" ixz="-0.0" iyy="1.3e-05" iyz="8e-06" izz="1.3e-05"/>
    </inertial>
    <visual>
      <origin rpy="0 0 0" xyz="0.305517 0.323851 -0.050585"/>
      <geometry>
        <mesh filename="/home/ilabs/Desktop/amr_ws/src/amr_ust_description/meshes/roller_4_3.stl" scale="0.001 0.001 0.001"/>
      </geometry>
      <material name="black"/>
    </visual>
    <collision>
      <origin rpy="0 0 0" xyz="0.305517 0.323851 -0.050585"/>
      <geometry>
        <mesh filename="/home/ilabs/Desktop/amr_ws/src/amr_ust_description/meshes/roller_4_3.stl" scale="0.001 0.001 0.001"/>
      </geometry>
    </collision>
  </link>
  <link name="roller_4_4">
    <inertial>
      <origin rpy="0 0 0" xyz="0.012628656360274326 0.017859997380225867 -0.012628700144894174"/>
      <mass value="0.10437828701391043"/>
      <inertia ixx="1.7e-05" ixy="-6e-06" ixz="4e-06" iyy="1.3e-05" iyz="6e-06" izz="1.7e-05"/>
    </inertial>
    <visual>
      <origin rpy="0 0 0" xyz="0.306985 0.323851 -0.018911"/>
      <geometry>
        <mesh filename="/home/ilabs/Desktop/amr_ws/src/amr_ust_description/meshes/roller_4_4.stl" scale="0.001 0.001 0.001"/>
      </geometry>
      <material name="black"/>
    </visual>
    <collision>
      <origin rpy="0 0 0" xyz="0.306985 0.323851 -0.018911"/>
      <geometry>
        <mesh filename="/home/ilabs/Desktop/amr_ws/src/amr_ust_description/meshes/roller_4_4.stl" scale="0.001 0.001 0.001"/>
      </geometry>
    </collision>
  </link>
  <link name="roller_4_5">
    <inertial>
      <origin rpy="0 0 0" xyz="0.01785955752109908 0.01785999738260663 -1.410332553866689e-10"/>
      <mass value="0.10437828701391043"/>
      <inertia ixx="1.3e-05" ixy="-8e-06" ixz="-0.0" iyy="1.3e-05" iyz="0.0" izz="2.1e-05"/>
    </inertial>
    <visual>
      <origin rpy="0 0 0" xyz="0.285626 0.323851 0.004524"/>
      <geometry>
        <mesh filename="/home/ilabs/Desktop/amr_ws/src/amr_ust_description/meshes/roller_4_5.stl" scale="0.001 0.001 0.001"/>
      </geometry>
      <material name="black"/>
    </visual>
    <collision>
      <origin rpy="0 0 0" xyz="0.285626 0.323851 0.004524"/>
      <geometry>
        <mesh filename="/home/ilabs/Desktop/amr_ws/src/amr_ust_description/meshes/roller_4_5.stl" scale="0.001 0.001 0.001"/>
      </geometry>
    </collision>
  </link>
  <link name="roller_4_6">
    <inertial>
      <origin rpy="0 0 0" xyz="0.01262866494926565 0.017859997380236026 0.01262869127383642"/>
      <mass value="0.10437828701391043"/>
      <inertia ixx="1.7e-05" ixy="-6e-06" ixz="-4e-06" iyy="1.3e-05" iyz="-6e-06" izz="1.7e-05"/>
    </inertial>
    <visual>
      <origin rpy="0 0 0" xyz="0.253952 0.323851 0.005992"/>
      <geometry>
        <mesh filename="/home/ilabs/Desktop/amr_ws/src/amr_ust_description/meshes/roller_4_6.stl" scale="0.001 0.001 0.001"/>
      </geometry>
      <material name="black"/>
    </visual>
    <collision>
      <origin rpy="0 0 0" xyz="0.253952 0.323851 0.005992"/>
      <geometry>
        <mesh filename="/home/ilabs/Desktop/amr_ws/src/amr_ust_description/meshes/roller_4_6.stl" scale="0.001 0.001 0.001"/>
      </geometry>
    </collision>
  </link>
  <link name="roller_4_7">
    <inertial>
      <origin rpy="0 0 0" xyz="-3.505335779974139e-08 0.01785999737700683 0.017859592431082198"/>
      <mass value="0.10437828701391043"/>
      <inertia ixx="2.1e-05" ixy="0.0" ixz="-0.0" iyy="1.3e-05" iyz="-8e-06" izz="1.3e-05"/>
    </inertial>
    <visual>
      <origin rpy="0 0 0" xyz="0.230517 0.323851 -0.015367"/>
      <geometry>
        <mesh filename="/home/ilabs/Desktop/amr_ws/src/amr_ust_description/meshes/roller_4_7.stl" scale="0.001 0.001 0.001"/>
      </geometry>
      <material name="black"/>
    </visual>
    <collision>
      <origin rpy="0 0 0" xyz="0.230517 0.323851 -0.015367"/>
      <geometry>
        <mesh filename="/home/ilabs/Desktop/amr_ws/src/amr_ust_description/meshes/roller_4_7.stl" scale="0.001 0.001 0.001"/>
      </geometry>
    </collision>
  </link>
  <link name="roller_4_8">
    <inertial>
      <origin rpy="0 0 0" xyz="-0.012628726464847917 0.01785999737377375 0.01262869985821194"/>
      <mass value="0.10437828701391043"/>
      <inertia ixx="1.7e-05" ixy="6e-06" ixz="4e-06" iyy="1.3e-05" iyz="-6e-06" izz="1.7e-05"/>
    </inertial>
    <visual>
      <origin rpy="0 0 0" xyz="0.229049 0.323851 -0.047041"/>
      <geometry>
        <mesh filename="/home/ilabs/Desktop/amr_ws/src/amr_ust_description/meshes/roller_4_8.stl" scale="0.001 0.001 0.001"/>
      </geometry>
      <material name="black"/>
    </visual>
    <collision>
      <origin rpy="0 0 0" xyz="0.229049 0.323851 -0.047041"/>
      <geometry>
        <mesh filename="/home/ilabs/Desktop/amr_ws/src/amr_ust_description/meshes/roller_4_8.stl" scale="0.001 0.001 0.001"/>
      </geometry>
    </collision>
  </link>
  <link name="imu_1">
    <inertial>
      <origin rpy="0 0 0" xyz="-0.0037135131762633944 0.00015074437785556966 -7.192465925183467e-06"/>
      <mass value="0.027981306586696276"/>
      <inertia ixx="4e-06" ixy="-0.0" ixz="0.0" iyy="2e-06" iyz="0.0" izz="2e-06"/>
    </inertial>
    <visual>
      <origin rpy="0 0 0" xyz="0.331142 0.000425 -0.054538"/>
      <geometry>
        <mesh filename="/home/ilabs/Desktop/amr_ws/src/amr_ust_description/meshes/imu_1.stl" scale="0.001 0.001 0.001"/>
      </geometry>
      <material name="silver"/>
    </visual>
    <collision>
      <origin rpy="0 0 0" xyz="0.331142 0.000425 -0.054538"/>
      <geometry>
        <mesh filename="/home/ilabs/Desktop/amr_ws/src/amr_ust_description/meshes/imu_1.stl" scale="0.001 0.001 0.001"/>
      </geometry>
    </collision>
  </link>
  <link name="Camera_1">
    <inertial>
      <origin rpy="0 0 0" xyz="0.017956856789517806 2.2171102201271888e-05 0.00015529819733451494"/>
      <mass value="0.378261563112952"/>
      <inertia ixx="7.7e-05" ixy="-0.0" ixz="1e-06" iyy="9.5e-05" iyz="0.0" izz="9.3e-05"/>
    </inertial>
    <visual>
      <origin rpy="0 0 0" xyz="-0.331142 -0.000425 -0.054538"/>
      <geometry>
        <mesh filename="/home/ilabs/Desktop/amr_ws/src/amr_ust_description/meshes/Camera_1.stl" scale="0.001 0.001 0.001"/>
      </geometry>
      <material name="silver"/>
    </visual>
    <collision>
      <origin rpy="0 0 0" xyz="-0.331142 -0.000425 -0.054538"/>
      <geometry>
        <mesh filename="/home/ilabs/Desktop/amr_ws/src/amr_ust_description/meshes/Camera_1.stl" scale="0.001 0.001 0.001"/>
      </geometry>
    </collision>
  </link>
  <link name="Intel_Realsense_RPLIDAR_1">
    <inertial>
      <origin rpy="0 0 0" xyz="0.024168716871690317 0.00016153042204601072 0.023318927009167684"/>
      <mass value="1.5656994294737245"/>
      <inertia ixx="0.000799" ixy="-0.0" ixz="0.0" iyy="0.000843" iyz="-2.9e-05" izz="0.001052"/>
    </inertial>
    <visual>
      <origin rpy="0 0 0" xyz="0.024557 0.000233 -0.105076"/>
      <geometry>
        <mesh filename="/home/ilabs/Desktop/amr_ws/src/amr_ust_description/meshes/Intel_Realsense_RPLIDAR_1.stl" scale="0.001 0.001 0.001"/>
      </geometry>
      <material name="black"/>
    </visual>
    <collision>
      <origin rpy="0 0 0" xyz="0.024557 0.000233 -0.105076"/>
      <geometry>
        <mesh filename="/home/ilabs/Desktop/amr_ws/src/amr_ust_description/meshes/Intel_Realsense_RPLIDAR_1.stl" scale="0.001 0.001 0.001"/>
      </geometry>
    </collision>
  </link>
  <joint name="Revolute 1" type="continuous">
    <origin rpy="0 0 0" xyz="0.244627 0.278967 0.032976"/>
    <parent link="base_link"/>
    <child link="wheel_hub_1"/>
    <axis xyz="-0.0 1.0 0.0"/>
  </joint>
  <joint name="Revolute 2" type="continuous">
    <origin rpy="0 0 0" xyz="0.244627 -0.279033 0.032976"/>
    <parent link="base_link"/>
    <child link="wheel_hub_2_1"/>
    <axis xyz="0.0 -1.0 0.0"/>
  </joint>
  <joint name="Revolute 3" type="continuous">
    <origin rpy="0 0 0" xyz="-0.268017 0.278467 0.032976"/>
    <parent link="base_link"/>
    <child link="wheel_hub_3_1"/>
    <axis xyz="-0.0 1.0 0.0"/>
  </joint>
  <joint name="Revolute 4" type="continuous">
    <origin rpy="0 0 0" xyz="-0.268017 -0.279533 0.032976"/>
    <parent link="base_link"/>
    <child link="wheel_hub_4_1"/>
    <axis xyz="0.0 -1.0 0.0"/>
  </joint>
  <joint name="Revolute 5" type="continuous">
    <origin rpy="0 0 0" xyz="-0.017609 0.044317 0.0375"/>
    <parent link="wheel_hub_1"/>
    <child link="roller_1_1"/>
    <axis xyz="0.707107 -0.707107 0.0"/>
  </joint>
  <joint name="Revolute 6" type="continuous">
    <origin rpy="0 0 0" xyz="0.014065 0.044317 0.038968"/>
    <parent link="wheel_hub_1"/>
    <child link="roller_1_2"/>
    <axis xyz="0.5 -0.707107 -0.5"/>
  </joint>
  <joint name="Revolute 7" type="continuous">
    <origin rpy="0 0 0" xyz="0.0375 0.044317 0.017609"/>
    <parent link="wheel_hub_1"/>
    <child link="roller_1_3"/>
    <axis xyz="0.0 -0.707107 -0.707107"/>
  </joint>
  <joint name="Revolute 8" type="continuous">
    <origin rpy="0 0 0" xyz="0.038968 0.044317 -0.014065"/>
    <parent link="wheel_hub_1"/>
    <child link="roller_1_4"/>
    <axis xyz="-0.5 -0.707107 -0.5"/>
  </joint>
  <joint name="Revolute 9" type="continuous">
    <origin rpy="0 0 0" xyz="0.017609 0.044317 -0.0375"/>
    <parent link="wheel_hub_1"/>
    <child link="roller_1_5"/>
    <axis xyz="-0.707107 -0.707107 -0.0"/>
  </joint>
  <joint name="Revolute 10" type="continuous">
    <origin rpy="0 0 0" xyz="-0.014065 0.044317 -0.038968"/>
    <parent link="wheel_hub_1"/>
    <child link="roller_1_6"/>
    <axis xyz="-0.5 -0.707107 0.5"/>
  </joint>
  <joint name="Revolute 11" type="continuous">
    <origin rpy="0 0 0" xyz="-0.0375 0.044317 -0.017609"/>
    <parent link="wheel_hub_1"/>
    <child link="roller_1_7"/>
    <axis xyz="0.0 -0.707107 0.707107"/>
  </joint>
  <joint name="Revolute 12" type="continuous">
    <origin rpy="0 0 0" xyz="-0.038968 0.044317 0.014065"/>
    <parent link="wheel_hub_1"/>
    <child link="roller_1_8"/>
    <axis xyz="0.5 -0.707107 0.5"/>
  </joint>
  <joint name="Revolute 13" type="continuous">
    <origin rpy="0 0 0" xyz="0.014065 -0.044318 0.038968"/>
    <parent link="wheel_hub_2_1"/>
    <child link="roller_2_1"/>
    <axis xyz="0.5 0.707107 -0.5"/>
  </joint>
  <joint name="Revolute 14" type="continuous">
    <origin rpy="0 0 0" xyz="-0.017609 -0.044318 0.0375"/>
    <parent link="wheel_hub_2_1"/>
    <child link="roller_2_2"/>
    <axis xyz="0.707107 0.707107 0.0"/>
  </joint>
  <joint name="Revolute 15" type="continuous">
    <origin rpy="0 0 0" xyz="0.0375 -0.044318 0.017609"/>
    <parent link="wheel_hub_2_1"/>
    <child link="roller_2_3"/>
    <axis xyz="-0.0 0.707107 -0.707107"/>
  </joint>
  <joint name="Revolute 16" type="continuous">
    <origin rpy="0 0 0" xyz="0.038968 -0.044318 -0.014065"/>
    <parent link="wheel_hub_2_1"/>
    <child link="roller_2_4"/>
    <axis xyz="-0.5 0.707107 -0.5"/>
  </joint>
  <joint name="Revolute 17" type="continuous">
    <origin rpy="0 0 0" xyz="0.017609 -0.044318 -0.0375"/>
    <parent link="wheel_hub_2_1"/>
    <child link="roller_2_5"/>
    <axis xyz="-0.707107 0.707107 -0.0"/>
  </joint>
  <joint name="Revolute 18" type="continuous">
    <origin rpy="0 0 0" xyz="-0.014065 -0.044318 -0.038968"/>
    <parent link="wheel_hub_2_1"/>
    <child link="roller_2_6"/>
    <axis xyz="-0.5 0.707107 0.5"/>
  </joint>
  <joint name="Revolute 19" type="continuous">
    <origin rpy="0 0 0" xyz="-0.0375 -0.044318 -0.017609"/>
    <parent link="wheel_hub_2_1"/>
    <child link="roller_2_7"/>
    <axis xyz="-0.0 0.707107 0.707107"/>
  </joint>
  <joint name="Revolute 20" type="continuous">
    <origin rpy="0 0 0" xyz="-0.038968 -0.044318 0.014065"/>
    <parent link="wheel_hub_2_1"/>
    <child link="roller_2_8"/>
    <axis xyz="0.5 0.707107 0.5"/>
  </joint>
  <joint name="Revolute 21" type="continuous">
    <origin rpy="0 0 0" xyz="0.017609 0.044317 0.0375"/>
    <parent link="wheel_hub_3_1"/>
    <child link="roller_3_1"/>
    <axis xyz="-0.707107 -0.707107 0.0"/>
  </joint>
  <joint name="Revolute 22" type="continuous">
    <origin rpy="0 0 0" xyz="-0.014065 0.044317 0.038968"/>
    <parent link="wheel_hub_3_1"/>
    <child link="roller_3_2"/>
    <axis xyz="-0.5 -0.707107 -0.5"/>
  </joint>
  <joint name="Revolute 23" type="continuous">
    <origin rpy="0 0 0" xyz="-0.0375 0.044317 0.017609"/>
    <parent link="wheel_hub_3_1"/>
    <child link="roller_3_3"/>
    <axis xyz="0.0 -0.707107 -0.707107"/>
  </joint>
  <joint name="Revolute 24" type="continuous">
    <origin rpy="0 0 0" xyz="-0.038968 0.044317 -0.014065"/>
    <parent link="wheel_hub_3_1"/>
    <child link="roller_3_4"/>
    <axis xyz="0.5 -0.707107 -0.5"/>
  </joint>
  <joint name="Revolute 25" type="continuous">
    <origin rpy="0 0 0" xyz="-0.017609 0.044317 -0.0375"/>
    <parent link="wheel_hub_3_1"/>
    <child link="roller_3_5"/>
    <axis xyz="0.707107 -0.707107 -0.0"/>
  </joint>
  <joint name="Revolute 26" type="continuous">
    <origin rpy="0 0 0" xyz="0.014065 0.044317 -0.038968"/>
    <parent link="wheel_hub_3_1"/>
    <child link="roller_3_6"/>
    <axis xyz="0.5 -0.707107 0.5"/>
  </joint>
  <joint name="Revolute 27" type="continuous">
    <origin rpy="0 0 0" xyz="0.038968 0.044317 0.014065"/>
    <parent link="wheel_hub_3_1"/>
    <child link="roller_3_7"/>
    <axis xyz="-0.5 -0.707107 0.5"/>
  </joint>
  <joint name="Revolute 28" type="continuous">
    <origin rpy="0 0 0" xyz="0.0375 0.044317 -0.017609"/>
    <parent link="wheel_hub_3_1"/>
    <child link="roller_3_8"/>
    <axis xyz="0.0 -0.707107 0.707107"/>
  </joint>
  <joint name="Revolute 29" type="continuous">
    <origin rpy="0 0 0" xyz="0.017609 -0.044318 0.0375"/>
    <parent link="wheel_hub_4_1"/>
    <child link="roller_4_1"/>
    <axis xyz="-0.707107 0.707107 -0.0"/>
  </joint>
  <joint name="Revolute 30" type="continuous">
    <origin rpy="0 0 0" xyz="-0.014065 -0.044318 0.038968"/>
    <parent link="wheel_hub_4_1"/>
    <child link="roller_4_2"/>
    <axis xyz="-0.5 0.707107 -0.5"/>
  </joint>
  <joint name="Revolute 31" type="continuous">
    <origin rpy="0 0 0" xyz="-0.0375 -0.044318 0.017609"/>
    <parent link="wheel_hub_4_1"/>
    <child link="roller_4_3"/>
    <axis xyz="-0.0 0.707107 -0.707107"/>
  </joint>
  <joint name="Revolute 32" type="continuous">
    <origin rpy="0 0 0" xyz="-0.038968 -0.044318 -0.014065"/>
    <parent link="wheel_hub_4_1"/>
    <child link="roller_4_4"/>
    <axis xyz="0.5 0.707107 -0.5"/>
  </joint>
  <joint name="Revolute 33" type="continuous">
    <origin rpy="0 0 0" xyz="-0.017609 -0.044318 -0.0375"/>
    <parent link="wheel_hub_4_1"/>
    <child link="roller_4_5"/>
    <axis xyz="0.707107 0.707107 -0.0"/>
  </joint>
  <joint name="Revolute 34" type="continuous">
    <origin rpy="0 0 0" xyz="0.014065 -0.044318 -0.038968"/>
    <parent link="wheel_hub_4_1"/>
    <child link="roller_4_6"/>
    <axis xyz="0.5 0.707107 0.5"/>
  </joint>
  <joint name="Revolute 35" type="continuous">
    <origin rpy="0 0 0" xyz="0.0375 -0.044318 -0.017609"/>
    <parent link="wheel_hub_4_1"/>
    <child link="roller_4_7"/>
    <axis xyz="-0.0 0.707107 0.707107"/>
  </joint>
  <joint name="Revolute 36" type="continuous">
    <origin rpy="0 0 0" xyz="0.038968 -0.044318 0.014065"/>
    <parent link="wheel_hub_4_1"/>
    <child link="roller_4_8"/>
    <axis xyz="-0.5 0.707107 0.5"/>
  </joint>
  <joint name="Rigid 37" type="fixed">
    <origin rpy="0 0 0" xyz="-0.331142 -0.000425 0.054538"/>
    <parent link="base_link"/>
    <child link="imu_1"/>
  </joint>
  <joint name="Rigid 40" type="fixed">
    <origin rpy="0 0 0" xyz="0.331142 0.000425 0.054538"/>
    <parent link="base_link"/>
    <child link="Camera_1"/>
  </joint>
  <joint name="Rigid 42" type="fixed">
    <origin rpy="0 0 0" xyz="-0.024557 -0.000233 0.105076"/>
    <parent link="base_link"/>
    <child link="Intel_Realsense_RPLIDAR_1"/>
  </joint>
</robot>
